<?xml version="1.0"?>
<robot xmlns:xacro="http://www.ros.org/wiki/xacro" name="barista_robot">

<!-- Robot Name -->
<xacro:property name="robot_name" value="$(arg robot_name)"/>

<!-- Main Body Dimensions-->
<xacro:property name="body_length" value="0.155"/>
<xacro:property name="body_radius" value="0.178"/>

<!-- Include Laser -->
<xacro:property name="include_laser" value="true"/>

<!-- Include Wheel Macro-->
<xacro:include filename="$(find barista_robot_description)/xacro/wheel.xacro" />

<!-- Include StandOff Macro-->
<xacro:include filename="$(find barista_robot_description)/xacro/standoff.xacro" />

<!-- Include Cup Holder Macro-->
<xacro:include filename="$(find barista_robot_description)/xacro/cup_holder_tray.xacro" />
     
<!-- Include Rviz Colors Macro-->

     
     
<link name="base_link">
  </link>

  <!-- Body -->
  <link name="chassis">
    <visual>
      <geometry>
        <cylinder length="${body_length}" radius="${body_radius}"/>
      </geometry>
      <material name="red"/>
    </visual>

    <collision>
      <geometry>
        <cylinder length="${body_length}" radius="${body_radius}"/>
      </geometry>
    </collision>

    <inertial>
      <mass value="2.92"/>
      <origin rpy="0 0 0" xyz="0 0 0"/>
      <inertia ixx="0.09052" ixy="0" ixz="0" iyy="0.09052" iyz="0" izz="0.03790"/>
    </inertial>

  </link>

  <gazebo reference="chassis">
        <material>Gazebo/Red</material>
  </gazebo>

   <joint name="base_link_joint" type="fixed">
    <origin rpy="0 0 0" xyz="0 0 0" />
    <parent link="base_link" />
    <child link="chassis" />
  </joint>

  
  <!-- Wheel Left -->
  <xacro:wheel wheel_name="left_wheel" />

  <gazebo reference="left_wheel">
    <kp>1000000000000000000000000000.0</kp>
    <kd>1000000000000000000000000000.0</kd>
    <mu1>10.0</mu1>
    <mu2>10.0</mu2>
    <material>Gazebo/Green</material>
  </gazebo>

  <joint name="joint_left_wheel" type="continuous">
    <origin rpy="0 0 0" xyz="0 0.128 -0.0775"/>
    <child link="left_wheel"/>
    <parent link="chassis"/>
    <axis rpy="0 0 0" xyz="0 1 0"/>
    <limit effort="10000" velocity="1000"/>
    <joint_properties damping="1.0" friction="1.0"/>
  </joint>

  <!-- Wheel Right -->
  <xacro:wheel wheel_name="right_wheel" />

  <gazebo reference="right_wheel">
    <kp>1000000000000000000000000000.0</kp>
    <kd>1000000000000000000000000000.0</kd>
    <mu1>10.0</mu1>
    <mu2>10.0</mu2>
    <material>Gazebo/Green</material>
  </gazebo>
  
  <joint name="joint_right_wheel" type="continuous">  
    <origin rpy="0 0 0" xyz="0 -0.128 -0.0775"/>
    <child link="right_wheel"/>
    <parent link="chassis"/>
    <axis rpy="0 0 0" xyz="0 1 0"/>
    <limit effort="10000" velocity="1000"/>
    <joint_properties damping="1.0" friction="1.0"/>
  </joint>

  <!-- Right Front Standoff -->
  <xacro:standoff standoff_name = "standoff_rod_right_front"/>

  <gazebo reference="standoff_rod_right_front">
        <material>Gazebo/Yellow</material>
  </gazebo>

  <joint name="standoff_off_right_front_joint" type="fixed">
    <origin rpy="0 0 0" xyz="0.040 0.128 0.1875" />
    <parent link="chassis" />
    <child link="standoff_rod_right_front" />
  </joint>

  <!-- Right Rear Standoff -->
  <xacro:standoff standoff_name = "standoff_rod_right_rear"/>

  <gazebo reference="standoff_rod_right_rear">
        <material>Gazebo/Yellow</material>
  </gazebo>

  <joint name="standoff_off_right_rear_joint" type="fixed">
    <origin rpy="0 0 0" xyz="-0.040 0.128 0.1875" />
    <parent link="chassis" />
    <child link="standoff_rod_right_rear" />
  </joint>


  <!-- Left Front Standoff -->
  <xacro:standoff standoff_name = "standoff_rod_left_front"/>

  <gazebo reference="standoff_rod_left_front">
        <material>Gazebo/Yellow</material>
  </gazebo>

  <joint name="standoff_off_left_front_joint" type="fixed">
    <origin rpy="0 0 0" xyz="0.040 -0.128 0.1875" />
    <parent link="chassis" />
    <child link="standoff_rod_left_front" />
  </joint>


  <!-- Left Rear Standoff -->  
  <xacro:standoff standoff_name = "standoff_rod_left_rear"/>

  <gazebo reference="standoff_rod_left_rear">
        <material>Gazebo/Yellow</material>
  </gazebo>

  <joint name="standoff_off_left_rear_joint" type="fixed">
    <origin rpy="0 0 0" xyz="-0.040 -0.128 0.1875" />
    <parent link="chassis" />
    <child link="standoff_rod_left_rear" />
  </joint>

  <!-- Cup Holder -->
  <xacro:cup_holder_tray cup_holder_tray_name = "cup_holder_tray" />

  <gazebo reference="cup_holder_tray">
        <material>Gazebo/Blue</material>
  </gazebo>

  <joint name="cup_holder_tray_joint" type="fixed">
    <origin rpy="0 0 0" xyz=" 0 0 0.3425" />
    <parent link="chassis" />
    <child link="cup_holder_tray" />
  </joint>

   <!-- Caster Wheel Front -->
  <link name="front_yaw_link">
    <visual>
    <origin rpy="0 1.5707 1.5707" xyz="0 0 0"/>
        <geometry>
            <cylinder length="0.0206" radius="0.0352"/>
        </geometry>
        <material name="blue"/>
    </visual>
    
    <inertial>
        <mass value="0.12"/>
        <origin rpy="0 0 0" xyz="0 0 0"/>
        <inertia ixx="0.00002727" ixy="0" ixz="0" iyy="0.00002727" iyz="0" izz=" 0.00002936"/>
    </inertial>

    <collision>
        <geometry>
            <cylinder length="0.0206" radius="0.0352"/>
        </geometry>
    </collision>
  </link>

  <joint name="front_yaw_joint" type="continuous">
        <origin rpy="0 0 0" xyz="0.128 0 -0.0775" />
        <parent link="chassis" />
        <child link="front_yaw_link" />
        <axis xyz="0 0 1" />
        <limit effort="1000.0" velocity="100.0" />
        <dynamics damping="0.0" friction="0.1"/>
  </joint>

  <gazebo reference="front_yaw_link">
        <material>Gazebo/Blue</material>
  </gazebo>

  <link name="front_roll_link">
    <visual>
        <origin rpy="0 1.5707 1.5707" xyz="0 0 0"/>
        <geometry>
            <cylinder length="0.0206" radius="0.0352"/>
        </geometry>
        <material name="red"/>
    </visual>

    <inertial>
        <mass value="0.12"/>
        <origin rpy="0 0 0" xyz="0 0 0"/>
        <inertia ixx="0.00002727" ixy="0" ixz="0" iyy="0.00002727" iyz="0" izz=" 0.00002936"/>
    </inertial>

    <collision>
        <geometry>
            <cylinder length="0.0206" radius="0.0352"/>
        </geometry>
    </collision>
  </link>

  <joint name="front_roll_joint" type="continuous">
        <origin rpy="0 0 0" xyz="0 0 0" />
        <parent link="front_yaw_link" />
        <child link="front_roll_link" />
        <axis xyz="1 0 0" />
        <limit effort="1000.0" velocity="100.0" />
        <dynamics damping="0.0" friction="0.1"/>
  </joint>

   <gazebo reference="front_roll_link">
        <material>Gazebo/Red</material>
   </gazebo>


  <link name="front_pitch_link">
    <visual>
        <origin rpy="0 1.5707 1.5707" xyz="0 0 0"/>
        <geometry>
            <sphere radius="0.0352"/>
        </geometry>
        <material name="green_dark"/>
    </visual>

    <inertial>
        <mass value="0.11"/>
        <origin rpy="0 0 0" xyz="0 0 0"/>
        <inertia ixx="0.00005395" ixy="0" ixz="0" iyy="0.00005395" iyz="0" izz="0.00005395"/>
    </inertial>

    <collision>
        <geometry>
            <sphere radius="0.0352"/>
        </geometry>
        </collision>
  </link>

  <gazebo reference="front_pitch_link">
    <kp>1000000000000000000000000000.0</kp>
    <kd>1000000000000000000000000000.0</kd>
    <mu1>0.5</mu1>
    <mu2>0.5</mu2>
    <material>Gazebo/Purple</material>
  </gazebo>

  <joint name="front_pitch_joint" type="continuous">
        <origin rpy="0 0 0" xyz="0 0 0" />
        <parent link="front_roll_link" />
        <child link="front_pitch_link" />
        <axis xyz="0 1 0" />
        <limit effort="1000.0" velocity="100.0" />
        <dynamics damping="0.0" friction="0.1"/>
  </joint>

<!-- Caster Wheel Back -->
  <link name="back_yaw_link">
    <visual>
        <origin rpy="0 1.5707 1.5707" xyz="0 0 0"/>
        <geometry>
          <cylinder length="0.0206" radius="0.0352"/>
        </geometry>
        <material name="blue"/>
      </visual>

    <inertial>
        <mass value="0.12"/>
        <origin rpy="0 0 0" xyz="0 0 0"/>
        <inertia ixx="0.00002727" ixy="0" ixz="0" iyy="0.00002727" iyz="0" izz=" 0.00002936"/>
    </inertial>

    <collision>
        <geometry>
            <cylinder length="0.0206" radius="0.0352"/>
        </geometry>
        </collision>
  </link>

  <joint name="back_yaw_joint" type="continuous">
        <origin rpy="0 0 0" xyz="-0.128 0 -0.0775" />
        <parent link="chassis" />
        <child link="back_yaw_link" />
        <axis xyz="0 0 1" />
        <limit effort="1000.0" velocity="100.0" />
        <dynamics damping="0.0" friction="0.1"/>
  </joint>

  <gazebo reference="back_yaw_link">
        <material>Gazebo/Blue</material>
  </gazebo>

  <link name="back_roll_link">
    <visual>
        <origin rpy="0 1.5707 1.5707" xyz="0 0 0"/>
        <geometry>
          <cylinder length="0.0206" radius="0.0352"/>
        </geometry>
        <material name="red"/>
    </visual>

    <inertial>
        <mass value="0.12"/>
        <origin rpy="0 0 0" xyz="0 0 0"/>
        <inertia ixx="0.00002727" ixy="0" ixz="0" iyy="0.00002727" iyz="0" izz=" 0.00002936"/>
    </inertial>

    <collision>
        <geometry>
            <cylinder length="0.0206" radius="0.0352"/>
        </geometry>
    </collision>

  </link>

  <joint name="back_roll_joint" type="continuous">
        <origin rpy="0 0 0" xyz="0 0 0" />
        <parent link="back_yaw_link" />
        <child link="back_roll_link" />
        <axis xyz="1 0 0" />
        <limit effort="1000.0" velocity="100.0" />
        <dynamics damping="0.0" friction="0.1"/>
  </joint>

   <gazebo reference="back_roll_link">
        <material>Gazebo/Red</material>
   </gazebo>


  <link name="back_pitch_link">
    <visual>
        <origin rpy="0 1.5707 1.5707" xyz="0 0 0"/>
        <geometry>
            <sphere radius="0.0352"/>
        </geometry>
        <material name="green_light"/>
    </visual>

    <inertial>
        <mass value="0.11"/>
        <origin rpy="0 0 0" xyz="0 0 0"/>
        <inertia ixx="0.00005395" ixy="0" ixz="0" iyy="0.00005395" iyz="0" izz="0.00005395"/>
    </inertial>

    <collision>
        <geometry>
            <sphere radius="0.0352"/>
        </geometry>
    </collision>

  </link>

  <gazebo reference="back_pitch_link">
    <kp>1000000000000000000000000000.0</kp>
    <kd>1000000000000000000000000000.0</kd>
    <mu1>0.5</mu1>
    <mu2>0.5</mu2>
    <material>Gazebo/Yellow</material>
  </gazebo>

  <joint name="back_pitch_joint" type="continuous">
    <origin rpy="0 0 0" xyz="0 0 0" />
    <parent link="back_roll_link" />
    <child link="back_pitch_link" />
    <axis xyz="0 1 0" />
    <limit effort="1000.0" velocity="100.0" />
    <dynamics damping="0.0" friction="0.1"/>
  </joint>


    <!-- Rviz Colors Macro -->
    <material name="green_dark">
        <color rgba="0.0 0.5 0.0 1"/>
    </material>


    <material name="white">
        <color rgba="1.0 1.0 1.0 1"/>
    </material>

    <material name="box_bot_blue">
        <color rgba="0.088656 0.428691 0.491021 1"/>
  </material>
  
  <!-- PLUGINS -->

  <!-- JOINT PUBLISHER -->
  <gazebo>
    <plugin name="box_bot_joint_state" filename="libgazebo_ros_joint_state_publisher.so">
      <ros>
          <namespace>/${robot_name}</namespace>
          <remapping>~/out:=joint_states</remapping>
      </ros>
      <update_rate>30</update_rate>

      <joint_name>joint_left_wheel</joint_name>
      <joint_name>joint_right_wheel</joint_name>
      <joint_name>front_yaw_joint</joint_name>
      <joint_name>back_yaw_joint</joint_name>
      <joint_name>front_roll_joint</joint_name>
      <joint_name>back_roll_joint</joint_name>
      <joint_name>front_pitch_joint</joint_name>
      <joint_name>back_pitch_joint</joint_name>
      
    </plugin>
  </gazebo>

   <!-- Differential drive -->
  <gazebo>
    <plugin filename="libgazebo_ros_diff_drive.so" name="differential_drive_controller">

      <ros>
          <namespace>/${robot_name}</namespace>
          <remapping>/cmd_vel:=cmd_vel</remapping>
      </ros>

      <!-- wheels -->
      <left_joint>joint_left_wheel</left_joint>
      <right_joint>joint_right_wheel</right_joint>

      <!-- kinematics -->
      <wheel_separation>0.3354</wheel_separation>
      <wheel_diameter>0.0704</wheel_diameter>

      <!-- limits -->
      <max_wheel_torque>3.0</max_wheel_torque>
      <max_wheel_acceleration>2.0</max_wheel_acceleration>

      <!-- output -->
      <publish_odom>true</publish_odom>
      <publish_odom_tf>true</publish_odom_tf>

      <odometry_frame>odom</odometry_frame>
      <robot_base_frame>base_link</robot_base_frame>

    </plugin>
  </gazebo>

  <!-- Laser Scan -->
  <xacro:arg name="include_laser" default="true"/>
    <xacro:if value="${include_laser}">
        
        <!-- Include Laser Scan -->
        <xacro:include filename="$(find barista_robot_description)/xacro/laser_scanner.xacro" />

        <xacro:laser_scan laser_scan_name= "laser_scan_link" />

        <gazebo reference="laser_scan_link">
            <material>Gazebo/Black</material>
        </gazebo>

        <joint name="laser_scan_link_joint" type="fixed">
            <origin rpy="0 0 0" xyz="0.0 0.0 0.0780"/>
            <parent link="chassis"/>
            <child link="laser_scan_link"/>
        </joint>

        <link name="laser_scan_frame">
        </link>

        <joint name="laser_scan_frame_joint" type="fixed">
            <origin rpy="0 0 0" xyz="0 0 0.03"/>
            <parent link="laser_scan_link"/>
            <child link="laser_scan_frame"/>
            <axis xyz="0 0 0"/>
        </joint>

        <gazebo reference="laser_scan_frame">
            <sensor name="sensor_ray" type="ray">
                <pose>0 0 0 0 0 0</pose>
                <ray>
                <scan>
                    <horizontal>
                    <samples>200</samples>
                    <resolution>1.0</resolution>
                    <min_angle>-3.14</min_angle>
                    <max_angle>3.14</max_angle>
                    </horizontal>
                </scan>
                <range>
                    <min>0.356</min>
                    <max>5.0</max>
                </range>
                </ray>
                <always_on>true</always_on>
                <visualize>true</visualize>
                <update_rate>100.0</update_rate>
                <plugin name="laser" filename="libgazebo_ros_ray_sensor.so">
                <ros>
                    <namespace>/${robot_name}</namespace>
                    <remapping>~/out:=scan</remapping>
                </ros>
                <output_type>sensor_msgs/LaserScan</output_type>
                </plugin>
            </sensor>
        </gazebo>

  </xacro:if>
    

</robot>